<?xml version="1.0"?>
<robot name="mira">

    <material name="red">
        <color rgba="0.8 0 0 1"/>
    </material>

    <material name="green">
        <color rgba="0 0.8 0 1"/>
    </material>

    <material name="blue">
        <color rgba="0 0 0.8 1"/>
    </material>

    <link name="base_link">
        <visual>
        <origin rpy="0 0 0" xyz="0 0 0"/>
        <geometry>
            <cylinder radius="0.06" length="0.18"/>
        </geometry>
        <material name="green"/>
        </visual>
    </link>
  
    <link name="roll_M1_link">
        <visual>
            <origin rpy="0 0 0" xyz="0 0 0"/>
            <geometry>
                <box size="0.15 0.15 0.12"/>
            </geometry>
            <material name="blue"/>
        </visual>
    </link>
    
    <joint name="roll_joint" type="revolute">
    <!-- <joint name="roll_joint" type="continuous"> -->
        <parent link="base_link"/>
        <child link="roll_M1_link"/>
        <origin xyz="0.0 0.0 0.0" rpy="0 0 0"/>
        <!-- <limit effort="0.1" velocity="0.005"/> -->
        <limit lower="-0.2" upper="0.2" effort="0.1" velocity="0.005"/> 
        <axis xyz="1 0 0"/>
    </joint>
  
</robot>